<?xml version="1.0" ?>

<robot name="robot">
  <link name="base_link"/>

  <link name="box_link">
    <inertial>
      <mass value="5"/>
      <origin xyz="0 0 0"/>
      <inertia ixx="0.035" ixy="0" ixz="0" iyy="0.060" iyz="0" izz="0.077"/>
    </inertial>
    <visual>
      <origin rpy="0 0 0" xyz="0 0 0"/>
        <geometry>
          <box size="0.35 0.25 0.15"/>
        </geometry>
    </visual>
    <collision>
      <origin rpy="0 0 0" xyz="0 0 0"/>
      <geometry>
        <box size="0.35 0.25 0.15"/>
      </geometry>
    </collision>
  </link>

  <link name="left_wheel">
    <inertial>
      <mass value="5"/>
      <origin rpy="-1.57079635 0 0" xyz="0 0 0"/>
      <inertia ixx="0.01" ixy="0" ixz="0" iyy="0.01" iyz="0" izz="0.02"/>
    </inertial>
    <visual>
      <origin rpy="-1.57079635 0 0" xyz="0 0 0"/>
      <geometry>
        <cylinder length="0.04" radius="0.1"/>
      </geometry>
    </visual>
    <collision>
      <origin rpy="-1.57079635 0 0" xyz="0 0 0"/>
      <geometry>
        <cylinder length="0.04" radius="0.1"/>
      </geometry>
    </collision>
  </link>

  <link name="right_wheel">
    <inertial>
      <mass value="5"/>
      <origin rpy="-1.57079635 0 0" xyz="0 0 0"/>
      <inertia ixx="0.01" ixy="0" ixz="0" iyy="0.01" iyz="0" izz="0.02"/>
    </inertial>
    <visual>
      <origin rpy="-1.57079635 0 0" xyz="0 0 0"/>
      <geometry>
        <cylinder length="0.04" radius="0.1"/>
      </geometry>
    </visual>
    <collision>
      <origin rpy="-1.57079635 0 0" xyz="0 0 0"/>
      <geometry>
        <cylinder length="0.04" radius="0.1"/>
      </geometry>
    </collision>
  </link>

  <link name="support_wheel">
    <inertial>
      <mass value="0.1"/>
      <origin xyz="0 0 0"/>
      <inertia ixx="0.0001" ixy="0" ixz="0" iyy="0.0001" iyz="0" izz="0.0001"/>
    </inertial>
    <visual>
      <origin rpy="-1.57079635 0 0" xyz="0 0 0"/>
      <geometry>
        <sphere radius="0.05"/>
      </geometry>
    </visual>
    <collision>
      <origin rpy="-1.57079635 0 0" xyz="0 0 0"/>
      <geometry>
        <sphere radius="0.05"/>
      </geometry>
    </collision>
  </link>

  <link name="laser">
    <inertial>
      <mass value="0.1"/>
      <origin xyz="0 0 0"/>
      <inertia ixx="0.00015" ixy="0" ixz="0" iyy="0.00015" iyz="0" izz="0.00002"/>
    </inertial>
    <visual>
      <origin rpy="0 0 0" xyz="0 0 0  "/>
      <geometry>
        <cylinder radius="0.05" length="0.1"/>
      </geometry>
    </visual>
    <collision>
      <origin rpy="0 0 0" xyz="0 0 0"/>
      <geometry>
        <cylinder radius="0.05" length="0.1"/>
      </geometry>
    </collision>
  </link>

  <joint name="base_link_to_box_link" type="fixed">
    <origin rpy="0 0 0" xyz="-0.05 0 0.15"/>
    <parent link="base_link"/>
    <child link="box_link"/>
  </joint>

  <joint name="box_link_to_support_wheel" type="fixed">
    <origin rpy="0 0 0" xyz="-0.15 0 -0.1"/>
    <parent link="box_link"/>
    <child link="support_wheel"/>
  </joint>

  <joint name="box_link_to_left_wheel" type="continuous">
    <axis xyz="0 1 0"/>
    <origin rpy="0 0 0" xyz="0.05 0.145 -0.05"/>
    <parent link="box_link"/>
    <child link="left_wheel"/>
  </joint>

  <joint name="box_link_to_right_wheel" type="continuous">
    <axis xyz="0 1 0"/>
    <origin rpy="0 0 0" xyz="0.05 -0.145 -0.05"/>
    <parent link="box_link"/>
    <child link="right_wheel"/>
  </joint>

  <joint name="box_link_to_laser" type="fixed">
    <origin rpy="0 0 0" xyz="0.12 0 0.125"/>
    <parent link="box_link"/>
    <child link="laser"/>
  </joint>

  <transmission name="box_link_to_left_wheel_trans">
    <type>transmission_interface/SimpleTransmission</type>
    <joint name="box_link_to_left_wheel">
      <hardwareInterface>hardware_interface/VelocityJointInterface</hardwareInterface>
    </joint>
    <actuator name="left_wheel_motor">
      <mechanicalReduction>1</mechanicalReduction>
    </actuator>
  </transmission>

  <transmission name="box_link_to_right_wheel_trans">
    <type>transmission_interface/SimpleTransmission</type>
    <joint name="box_link_to_right_wheel">
      <hardwareInterface>hardware_interface/VelocityJointInterface</hardwareInterface>
    </joint>
    <actuator name="right_wheel_motor">
      <mechanicalReduction>-1</mechanicalReduction>
    </actuator>
  </transmission>

  <gazebo reference="left_wheel">
    <mu1>0.5</mu1>
    <mu2>50.0</mu2>
    <kp>100000000.0</kp>
    <kd>1.0</kd>
  </gazebo>

  <gazebo reference="right_wheel">
    <mu1>0.5</mu1>
    <mu2>50.0</mu2>
    <kp>100000000.0</kp>
    <kd>1.0</kd>
  </gazebo>

  <gazebo reference="support_wheel">
    <mu1>0.0</mu1>
    <mu2>0.0</mu2>
    <kp>1000000.0</kp>
    <kd>1.0</kd>
  </gazebo>

  <gazebo reference="laser">
    <sensor type="ray" name="laser_sensor">
      <pose>0 0 0 0 0 0</pose>
      <visualize>false</visualize>
      <update_rate>30</update_rate>
      <ray>
        <scan>
          <horizontal>
            <samples>720</samples>
            <resolution>1</resolution>
            <min_angle>-3.14159265359</min_angle>
            <max_angle>3.14159265359</max_angle>
          </horizontal>
        </scan>
        <range>
          <min>0.10</min>
          <max>30.0</max>
          <resolution>0.01</resolution>
        </range>
      </ray>
      <plugin name="gazebo_ros_laser" filename="libgazebo_ros_laser.so">
        <topicName>/laser/scan</topicName>
        <frameName>laser</frameName>
      </plugin>
    </sensor>
  </gazebo>

  <gazebo>
    <plugin filename="libgazebo_ros_control.so" name="gazebo_ros_control">
    </plugin>
  </gazebo>
</robot>

